<mujoco model="onshape">
  <compiler angle="radian"/>

  <asset>
    <mesh name="part_1" file="part_1.stl"/>
    <mesh name="part_2" file="part_2.stl"/>
    <mesh name="part_3" file="part_3.stl"/>
    <mesh name="part_4" file="part_4.stl"/>
  </asset>


    <option gravity="0 0 -9.81" timestep="0.001" iterations="5000">

   </option>

  <worldbody>

    <geom name="floor" type="plane" pos="0 0 0" size="10 10 1" rgba="0.8 0.8 0.8 1" friction="1.0 0.2 0.01" />

      <body name="main_body" pos="0 0 0.2">
      <freejoint name="root"/>
    <geom pos="-0.000171418 0.000240648 -0.0247441" quat="1 0 0 0" type="mesh" rgba="0.615686 0.811765 0.929412 1" mesh="part_1"/>
    <body name="part_2" pos="-0.0308041 0.0818578 -0.0197441" quat="0 -1 0 0">
      <inertial pos="0 0 -0.0225" mass="0.0225" diaginertia="4.54687e-06 4.54687e-06 1.5e-06"/>
      <joint name="1.1" pos="0 0 0" axis="0 0 1" range="-0.261799 0.261799" actuatorfrcrange="-10 10" damping="10"/>
      <geom pos="-0.0306327 -0.0816171 0.005" quat="0 1 0 0" type="mesh" rgba="0.647059 0.647059 0.647059 1" mesh="part_2"/>
      <body name="part_3" pos="0 -0.01 -0.0225" quat="0.707107 -0.707107 0 0">
        <inertial pos="-0.0474144 1.88489e-05 0.01" quat="0.500036 0.500036 0.499964 0.499964" mass="0.0449754" diaginertia="5.58559e-05 5.05429e-05 9.61719e-06"/>
        <joint name="2.1" pos="0 0 0" axis="0 0 1" range="-0.261799 0.261799" actuatorfrcrange="-10 10" damping="10"/>
        <geom pos="-0.128094 -0.02623 -0.0716171" quat="0.707107 -0.707107 0 0" type="mesh" rgba="0.917647 0.917647 0.917647 1" mesh="part_3"/>
        <body name="part_4" pos="-0.0949851 3.66516e-05 0.02" quat="1 0 0 0">
          <inertial pos="-5.73004e-09 -0.0276732 -0.01" quat="0.500021 0.500021 -0.499979 0.499979" mass="0.0309466" diaginertia="2.43319e-05 2.42547e-05 1.55077e-06"/>
          <joint name="3.4" pos="0 0 0" axis="0 0 1" range="-0.349066 0.349066" actuatorfrcrange="-10 10" damping="10"/>
          <geom pos="-0.128094 -0.02623 -0.0916171" quat="0.707107 -0.707107 0 0" type="mesh" rgba="0.768627 0.886275 0.952941 1" mesh="part_4"/>
        </body>
      </body>
    </body>
    <body name="part_2_2" pos="-0.0308041 0.000240648 -0.0197441" quat="0 -1 0 0">
      <inertial pos="0 0 -0.0225" mass="0.0225" diaginertia="4.54687e-06 4.54687e-06 1.5e-06"/>
      <joint name="1.2" pos="0 0 0" axis="0 0 1" range="-0.261799 0.261799" actuatorfrcrange="-10 10" damping="10"/>
      <geom pos="-0.0306327 0.0816171 -0.05" type="mesh" rgba="0.647059 0.647059 0.647059 1" mesh="part_2"/>
      <body name="part_3_2" pos="0 -0.01 -0.0225" quat="0.707107 -0.707107 0 0">
        <inertial pos="-0.0474144 1.88489e-05 0.01" quat="0.500036 0.500036 0.499964 0.499964" mass="0.0449754" diaginertia="5.58559e-05 5.05429e-05 9.61719e-06"/>
        <joint name="2.2" pos="0 0 0" axis="0 0 1" range="-0.261799 0.261799" actuatorfrcrange="-10 10" damping="10"/>
        <geom pos="-0.128094 -0.02623 -0.0716171" quat="0.707107 -0.707107 0 0" type="mesh" rgba="0.917647 0.917647 0.917647 1" mesh="part_3"/>
        <body name="part_4_2" pos="-0.0949851 3.66516e-05 0.02">
          <inertial pos="-5.73004e-09 -0.0276732 -0.01" quat="0.500021 0.500021 -0.499979 0.499979" mass="0.0309466" diaginertia="2.43319e-05 2.42547e-05 1.55077e-06"/>
          <joint name="3.6" pos="0 0 0" axis="0 0 1" range="-0.349066 0.349066" actuatorfrcrange="-10 10" damping="10"/>
          <geom pos="-0.128094 -0.02623 -0.0916171" quat="0.707107 -0.707107 0 0" type="mesh" rgba="0.768627 0.886275 0.952941 1" mesh="part_4"/>
        </body>
      </body>
    </body>
    <body name="part_2_3" pos="-0.0308041 -0.0813765 -0.0197441" quat="0 1 0 0">
      <inertial pos="0 0 -0.0225" mass="0.0225" diaginertia="4.54687e-06 4.54687e-06 1.5e-06"/>
      <joint name="1.3" pos="0 0 0" axis="0 0 1" range="-0.261799 0.261799" actuatorfrcrange="-10 10" damping="10"/>
      <geom pos="-0.0306327 0.0816171 -0.05" type="mesh" rgba="0.647059 0.647059 0.647059 1" mesh="part_2"/>
      <body name="part_3_3" pos="0 -0.01 -0.0225" quat="0.707107 -0.707107 0 0">
        <inertial pos="-0.0474144 1.88489e-05 0.01" quat="0.500036 0.500036 0.499964 0.499964" mass="0.0449754" diaginertia="5.58559e-05 5.05429e-05 9.61719e-06"/>
        <joint name="2.3" pos="0 0 0" axis="0 0 1" range="-0.261799 0.261799" actuatorfrcrange="-10 10" damping="10"/>
        <geom pos="-0.128094 -0.02623 -0.0716171" quat="0.707107 -0.707107 0 0" type="mesh" rgba="0.917647 0.917647 0.917647 1" mesh="part_3"/>
        <body name="part_4_3" pos="-0.0949851 3.66516e-05 0.02">
          <inertial pos="-5.73004e-09 -0.0276732 -0.01" quat="0.500021 0.500021 -0.499979 0.499979" mass="0.0309466" diaginertia="2.43319e-05 2.42547e-05 1.55077e-06"/>
          <joint name="3.5" pos="0 0 0" axis="0 0 1" range="-0.349066 0.349066" actuatorfrcrange="-10 10" damping="10"/>
          <geom pos="-0.128094 -0.02623 -0.0916171" quat="0.707107 -0.707107 0 0" type="mesh" rgba="0.768627 0.886275 0.952941 1" mesh="part_4"/>
        </body>
      </body>
    </body>
    <body name="part_2_4" pos="0.0304613 -0.0813765 -0.0197441" quat="0 1 0 0">
      <inertial pos="0 0 -0.0225" mass="0.0225" diaginertia="4.54687e-06 4.54687e-06 1.5e-06"/>
      <joint name="1.4" pos="0 0 0" axis="0 0 1" range="-0.261799 0.261799" actuatorfrcrange="-10 10" damping="10"/>
      <geom pos="-0.0306327 0.0816171 -0.05" type="mesh" rgba="0.647059 0.647059 0.647059 1" mesh="part_2"/>
      <body name="part_3_4" pos="0 0.01 -0.0225" quat="0.707107 0.707107 0 0">
        <inertial pos="0.0475707 1.78026e-05 0.01" quat="0.499964 0.499964 0.500036 0.500036" mass="0.0449754" diaginertia="5.58559e-05 5.05429e-05 9.61719e-06"/>
        <joint name="2.6" pos="0 0 0" axis="0 0 1" range="-0.261799 0.261799" actuatorfrcrange="-10 10" damping="10"/>
        <geom pos="-0.0331089 0.0262667 0.0916171" quat="0.707107 0.707107 0 0" type="mesh" rgba="0.917647 0.917647 0.917647 1" mesh="part_3"/>
        <body name="part_4_4" pos="0.0949851 3.66516e-05 0" quat="0 1 0 0">
          <inertial pos="-5.73004e-09 -0.0276732 -0.01" quat="0.500021 0.500021 -0.499979 0.499979" mass="0.0309466" diaginertia="2.43319e-05 2.42547e-05 1.55077e-06"/>
          <joint name="3.1" pos="0 0 0" axis="0 0 1" range="-0.349066 0.349066" actuatorfrcrange="-10 10" damping="10"/>
          <geom pos="-0.128094 -0.02623 -0.0916171" quat="0.707107 -0.707107 0 0" type="mesh" rgba="0.768627 0.886275 0.952941 1" mesh="part_4"/>
        </body>
      </body>
    </body>
    <body name="part_2_5" pos="0.0304613 0.000240648 -0.0197441" quat="0 1 0 0">
      <inertial pos="0 0 -0.0225" mass="0.0225" diaginertia="4.54687e-06 4.54687e-06 1.5e-06"/>
      <joint name="1.5" pos="0 0 0" axis="0 0 1" range="-0.261799 0.261799" actuatorfrcrange="-10 10" damping="10"/>
      <geom pos="-0.0306327 0.0816171 -0.05" type="mesh" rgba="0.647059 0.647059 0.647059 1" mesh="part_2"/>
      <body name="part_3_5" pos="0 0.01 -0.0225" quat="0 0 -0.707107 0.707107">
        <inertial pos="-0.0474144 -1.88489e-05 0.01" quat="0.499964 0.499964 0.500036 0.500036" mass="0.0449754" diaginertia="5.58559e-05 5.05429e-05 9.61719e-06"/>
        <joint name="2.4" pos="0 0 0" axis="0 0 1" range="-0.261799 0.261799" actuatorfrcrange="-10 10" damping="10"/>
        <geom pos="-0.128094 0.02623 0.0916171" quat="0.707107 0.707107 0 0" type="mesh" rgba="0.917647 0.917647 0.917647 1" mesh="part_3"/>
        <body name="part_4_5" pos="-0.0949851 -3.66516e-05 0" quat="0 0 1 0">
          <inertial pos="-5.73004e-09 -0.0276732 -0.01" quat="0.500021 0.500021 -0.499979 0.499979" mass="0.0309466" diaginertia="2.43319e-05 2.42547e-05 1.55077e-06"/>
          <joint name="3.2" pos="0 0 0" axis="0 0 1" range="-0.349066 0.349066" actuatorfrcrange="-10 10" damping="10"/>
          <geom pos="-0.128094 -0.02623 -0.0916171" quat="0.707107 -0.707107 0 0" type="mesh" rgba="0.768627 0.886275 0.952941 1" mesh="part_4"/>
        </body>
      </body>
    </body>
    <body name="part_2_6" pos="0.0304613 0.0818578 -0.0197441" quat="0 1 0 0">
      <inertial pos="0 0 -0.0225" mass="0.0225" diaginertia="4.54687e-06 4.54687e-06 1.5e-06"/>
      <joint name="1.6" pos="0 0 0" axis="0 0 1" range="-0.261799 0.261799" actuatorfrcrange="-10 10" damping="10"/>
      <geom pos="-0.0306327 0.0816171 -0.05" type="mesh" rgba="0.647059 0.647059 0.647059 1" mesh="part_2"/>
      <body name="part_3_6" pos="0 0.01 -0.0225" quat="0.707107 0.707107 0 0">
        <inertial pos="0.0475707 1.78026e-05 0.01" quat="0.499964 0.499964 0.500036 0.500036" mass="0.0449754" diaginertia="5.58559e-05 5.05429e-05 9.61719e-06"/>
        <joint name="2.5" pos="0 0 0" axis="0 0 1" range="-0.261799 0.261799" actuatorfrcrange="-10 10" damping="10"/>
        <geom pos="-0.0331089 0.0262667 0.0916171" quat="0.707107 0.707107 0 0" type="mesh" rgba="0.917647 0.917647 0.917647 1" mesh="part_3"/>
        <body name="part_4_6" pos="0.0949851 3.66516e-05 0" quat="0 1 0 0">
          <inertial pos="-5.73004e-09 -0.0276732 -0.01" quat="0.500021 0.500021 -0.499979 0.499979" mass="0.0309466" diaginertia="2.43319e-05 2.42547e-05 1.55077e-06"/>
          <joint name="3.3" pos="0 0 0" axis="0 0 1" range="-0.349066 0.349066" actuatorfrcrange="-10 10" damping="10"/>
          <geom pos="-0.128094 -0.02623 -0.0916171" quat="0.707107 -0.707107 0 0" type="mesh" rgba="0.768627 0.886275 0.952941 1" mesh="part_4"/>
        </body>
      </body>
    </body>
    </body>
  </worldbody>


<actuator>
    <!-- Actuators for joints 1.1 - 1.6 -->
    <position joint="1.1" ctrllimited="true" ctrlrange="-0.523599 0.523599" kp="100" timeconst="0.2"/>
    <position joint="1.2" ctrllimited="true" ctrlrange="-0.523599 0.523599" kp="100" timeconst="0.2"/>
    <position joint="1.3" ctrllimited="true" ctrlrange="-0.523599 0.523599" kp="100" timeconst="0.2"/>
    <position joint="1.4" ctrllimited="true" ctrlrange="-0.523599 0.523599" kp="100" timeconst="0.2"/>
    <position joint="1.5" ctrllimited="true" ctrlrange="-0.523599 0.523599" kp="100" timeconst="0.2"/>
    <position joint="1.6" ctrllimited="true" ctrlrange="-0.523599 0.523599" kp="100" timeconst="0.2"/>

    <!-- Actuators for joints 2.1 - 2.6 -->
    <position joint="2.1" ctrllimited="true" ctrlrange="-0.523599 0.523599" kp="100" timeconst="0.2"/>
    <position joint="2.2" ctrllimited="true" ctrlrange="-0.523599 0.523599" kp="100" timeconst="0.2"/>
    <position joint="2.3" ctrllimited="true" ctrlrange="-0.523599 0.523599" kp="100" timeconst="0.2"/>
    <position joint="2.4" ctrllimited="true" ctrlrange="-0.523599 0.523599" kp="100" timeconst="0.2"/>
    <position joint="2.5" ctrllimited="true" ctrlrange="-0.523599 0.523599" kp="100" timeconst="0.2"/>
    <position joint="2.6" ctrllimited="true" ctrlrange="-0.523599 0.523599" kp="100" timeconst="0.2"/>

    <!-- Actuators for joints 3.1 - 3.6 -->
    <position joint="3.1" ctrllimited="true" ctrlrange="-0.523599 0.523599" kp="100" timeconst="0.2"/>
    <position joint="3.2" ctrllimited="true" ctrlrange="-0.523599 0.523599" kp="100" timeconst="0.2"/>
    <position joint="3.3" ctrllimited="true" ctrlrange="-0.523599 0.523599" kp="100" timeconst="0.2"/>
    <position joint="3.4" ctrllimited="true" ctrlrange="-0.523599 0.523599" kp="100" timeconst="0.2"/>
    <position joint="3.5" ctrllimited="true" ctrlrange="-0.523599 0.523599" kp="100" timeconst="0.2"/>
    <position joint="3.6" ctrllimited="true" ctrlrange="-0.523599 0.523599" kp="100" timeconst="0.2"/>
</actuator>
</mujoco>
