<robot name="onshape">
<link name="mainbody">
<visual>
<origin xyz="0 0 -0.02999999999999999889" rpy="0 -0 0" />
<geometry>
<mesh filename="package:///mainbody.stl"/>
</geometry>
<material name="mainbody_material">
<color rgba="0.61568627450980395466 0.81176470588235294379 0.92941176470588238168 1.0"/>
</material>
</visual>
<collision>
<origin xyz="0 0 -0.02999999999999999889" rpy="0 -0 0" />
<geometry>
<mesh filename="package:///mainbody.stl"/>
</geometry>
</collision>
<inertial>
<origin xyz="-1.5402832622994170411e-08 3.159414464449913527e-08 -9.5440242549316156584e-09" rpy="0 0 0"/>
<mass value="0.47587710120400344982" />
<inertia ixx="0.0020497750060872845304" ixy="8.9133302511777448719e-10"  ixz="-2.496144636255833872e-10" iyy="0.0020497677659904595115" iyz="4.7168651638236494287e-10" izz="0.0034039318543897826783" />
</inertial>
</link>

<link name="arm1">
<visual>
<origin xyz="0.050000000000000002776 -6.360060536959987488e-18 -0.05300000000000000544" rpy="4.3790577010150533466e-47 -2.4651903288162464961e-32 0" />
<geometry>
<mesh filename="package:///arm1.stl"/>
</geometry>
<material name="arm1_material">
<color rgba="0.61568627450980395466 0.81176470588235294379 0.92941176470588238168 1.0"/>
</material>
</visual>
<collision>
<origin xyz="0.050000000000000002776 -6.360060536959987488e-18 -0.05300000000000000544" rpy="4.3790577010150533466e-47 -2.4651903288162464961e-32 0" />
<geometry>
<mesh filename="package:///arm1.stl"/>
</geometry>
</collision>
<inertial>
<origin xyz="0.050000000000000002776 2.8353822684379208939e-19 -0.027999999999999983236" rpy="0 0 0"/>
<mass value="0.053351215563702140965" />
<inertia ixx="4.7685000723111073309e-05" ixy="-1.2113303710964261991e-50"  ixz="1.175526026122662224e-36" iyy="0.00012294175838236645528" iyz="-2.3845280692264776134e-36" izz="9.6727950022912305016e-05" />
</inertial>
</link>

<link name="armtwo">
<visual>
<origin xyz="0.11000000000000001443 -1.232595164407830946e-32 -0.0029999999999999991951" rpy="3.141592653589793116 1.397534752336465342e-32 0" />
<geometry>
<mesh filename="package:///armtwo.stl"/>
</geometry>
<material name="armtwo_material">
<color rgba="0.61568627450980395466 0.81176470588235294379 0.92941176470588238168 1.0"/>
</material>
</visual>
<collision>
<origin xyz="0.11000000000000001443 -1.232595164407830946e-32 -0.0029999999999999991951" rpy="3.141592653589793116 1.397534752336465342e-32 0" />
<geometry>
<mesh filename="package:///armtwo.stl"/>
</geometry>
</collision>
<inertial>
<origin xyz="0.055000000000000028033 1.4878383531301146846e-18 -0.025000000000000008327" rpy="0 0 0"/>
<mass value="0.061604201110935161156" />
<inertia ixx="3.5201315914225203519e-05" ixy="-7.3831702027065888923e-36"  ixz="-1.2363033867340587757e-36" iyy="0.00018430582427480415148" iyz="-9.8974646700000273386e-37" izz="0.00016639677522796493558" />
</inertial>
</link>

<joint name="elbow4" type="revolute">
<origin xyz="0.10000000000000074107 6.4324295821863979682e-17 -0.0030000000000001275646" rpy="-3.9620612083441692385e-16 1.1288219435349461779e-15 2.3592239273284620857e-16" />
<parent link="arm1" />
<child link="armtwo" />
<axis xyz="0 0 1"/>
<limit effort="1" velocity="20" lower="-1.0471975511965976313" upper="1.0471975511965976313"/>
<joint_properties friction="0.0"/>
</joint>

<joint name="main1" type="revolute">
<origin xyz="-0.10000000000000000555 -0.033000000000000015432 -2.9230654844238226371e-17" rpy="-1.57079632679489678 -2.2204460492503120948e-16 -3.1415926535897926719" />
<parent link="mainbody" />
<child link="arm1" />
<axis xyz="0 0 1"/>
<limit effort="1" velocity="20" lower="-0.52359877559829881566" upper="0.52359877559829881566"/>
<joint_properties friction="0.0"/>
</joint>

<link name="arm1_2">
<visual>
<origin xyz="-0.050000000000000016653 -4.35411643674231891e-20 -0.05300000000000000544" rpy="1.4745382043742938381e-43 -4.8926167152818993738e-33 -8.3816471179732504325e-31" />
<geometry>
<mesh filename="package:///arm1.stl"/>
</geometry>
<material name="arm1_material">
<color rgba="0.61568627450980395466 0.81176470588235294379 0.92941176470588238168 1.0"/>
</material>
</visual>
<collision>
<origin xyz="-0.050000000000000016653 -4.35411643674231891e-20 -0.05300000000000000544" rpy="1.4745382043742938381e-43 -4.8926167152818993738e-33 -8.3816471179732504325e-31" />
<geometry>
<mesh filename="package:///arm1.stl"/>
</geometry>
</collision>
<inertial>
<origin xyz="-0.050000000000000009714 6.6000575994363561957e-18 -0.027999999999999983236" rpy="0 0 0"/>
<mass value="0.053351215563702140965" />
<inertia ixx="4.7685000723111073309e-05" ixy="6.9139055269707656235e-35"  ixz="9.5231567950057713544e-37" iyy="0.00012294175838236645528" iyz="1.8093286839633066385e-47" izz="9.6727950022912305016e-05" />
</inertial>
</link>

<link name="armtwo_2">
<visual>
<origin xyz="0 0 -0.0030000000000000026645" rpy="3.141592653589793116 4.9978446414737649065e-31 2.7117093616972280811e-31" />
<geometry>
<mesh filename="package:///armtwo.stl"/>
</geometry>
<material name="armtwo_material">
<color rgba="0.61568627450980395466 0.81176470588235294379 0.92941176470588238168 1.0"/>
</material>
</visual>
<collision>
<origin xyz="0 0 -0.0030000000000000026645" rpy="3.141592653589793116 4.9978446414737649065e-31 2.7117093616972280811e-31" />
<geometry>
<mesh filename="package:///armtwo.stl"/>
</geometry>
</collision>
<inertial>
<origin xyz="-0.0549999999999999864 1.4878383531301125661e-18 -0.025000000000000011796" rpy="0 0 0"/>
<mass value="0.061604201110935161156" />
<inertia ixx="3.5201315914225203519e-05" ixy="-6.3150255896425339867e-35"  ixz="-2.090116655180465545e-35" iyy="0.00018430582427480415148" iyz="-6.1519964843104896728e-35" izz="0.00016639677522796493558" />
</inertial>
</link>

<joint name="elbow3" type="revolute">
<origin xyz="-0.10000000000000006106 6.316519372592798492e-18 -0.0030000000000000026645" rpy="4.7555545829153164316e-15 5.3290705182007450831e-15 2.9198865547641566526e-14" />
<parent link="arm1_2" />
<child link="armtwo_2" />
<axis xyz="0 0 1"/>
<limit effort="1" velocity="20" lower="-1.0471975511965976313" upper="1.0471975511965976313"/>
<joint_properties friction="0.0"/>
</joint>

<joint name="main2" type="revolute">
<origin xyz="0.032999999999999980738 -0.099999999999999977796 0" rpy="1.570796326794896558 2.4646951146678468887e-14 1.57079632679489678" />
<parent link="mainbody" />
<child link="arm1_2" />
<axis xyz="0 0 1"/>
<limit effort="1" velocity="20" lower="-0.52359877559829881566" upper="0.52359877559829881566"/>
<joint_properties friction="0.0"/>
</joint>

<link name="arm1_3">
<visual>
<origin xyz="-0.04999999999999997502 -4.3541164367121203284e-20 -0.05300000000000000544" rpy="2.8520155610697452322e-32 3.312504220547771502e-32 -4.3140830754274083108e-32" />
<geometry>
<mesh filename="package:///arm1.stl"/>
</geometry>
<material name="arm1_material">
<color rgba="0.61568627450980395466 0.81176470588235294379 0.92941176470588238168 1.0"/>
</material>
</visual>
<collision>
<origin xyz="-0.04999999999999997502 -4.3541164367121203284e-20 -0.05300000000000000544" rpy="2.8520155610697452322e-32 3.312504220547771502e-32 -4.3140830754274083108e-32" />
<geometry>
<mesh filename="package:///arm1.stl"/>
</geometry>
</collision>
<inertial>
<origin xyz="-0.04999999999999997502 6.6000575994366589519e-18 -0.027999999999999983236" rpy="0 0 0"/>
<mass value="0.053351215563702140965" />
<inertia ixx="4.7685000723111073309e-05" ixy="8.361026865190425009e-36"  ixz="-2.7393384369768793247e-36" iyy="0.00012294175838236645528" iyz="3.2896439586958167932e-36" izz="9.6727950022912305016e-05" />
</inertial>
</link>

<link name="armtwo_3">
<visual>
<origin xyz="0 3.0814879110195773649e-33 -0.0029999999999999991951" rpy="3.141592653589793116 2.4756451462589628264e-32 -3.0814879110195773649e-32" />
<geometry>
<mesh filename="package:///armtwo.stl"/>
</geometry>
<material name="armtwo_material">
<color rgba="0.61568627450980395466 0.81176470588235294379 0.92941176470588238168 1.0"/>
</material>
</visual>
<collision>
<origin xyz="0 3.0814879110195773649e-33 -0.0029999999999999991951" rpy="3.141592653589793116 2.4756451462589628264e-32 -3.0814879110195773649e-32" />
<geometry>
<mesh filename="package:///armtwo.stl"/>
</geometry>
</collision>
<inertial>
<origin xyz="-0.0549999999999999864 1.487838353130130092e-18 -0.025000000000000008327" rpy="0 0 0"/>
<mass value="0.061604201110935161156" />
<inertia ixx="3.5201315914225203519e-05" ixy="2.6068608068919854788e-36"  ixz="1.8256743763494857164e-35" iyy="0.00018430582427480415148" iyz="-4.3946602698415056358e-35" izz="0.00016639677522796493558" />
</inertial>
</link>

<joint name="elbow2" type="revolute">
<origin xyz="-0.10000000000000001943 5.0051481209783796418e-18 -0.003000000000000006134" rpy="1.1512124667823426406e-15 -1.7407503007461796655e-15 -2.4980018054066007368e-16" />
<parent link="arm1_3" />
<child link="armtwo_3" />
<axis xyz="0 0 1"/>
<limit effort="1" velocity="20" lower="-1.0471975511965976313" upper="1.0471975511965976313"/>
<joint_properties friction="0.0"/>
</joint>

<joint name="main3" type="revolute">
<origin xyz="0.10000000000000000555 0.033000000000000008493 1.4700973434780587663e-18" rpy="1.570796326794896558 -3.7470027081099210733e-16 -3.1415926535897926719" />
<parent link="mainbody" />
<child link="arm1_3" />
<axis xyz="0 0 1"/>
<limit effort="1" velocity="20" lower="-0.52359877559829881566" upper="0.52359877559829881566"/>
<joint_properties friction="0.0"/>
</joint>

<link name="arm1_4">
<visual>
<origin xyz="-0.050000000000000030531 -4.3541164367115040308e-20 -0.05300000000000000544" rpy="-4.1963440962894192726e-32 -1.3606706459783137366e-31 -9.8607613152626475676e-32" />
<geometry>
<mesh filename="package:///arm1.stl"/>
</geometry>
<material name="arm1_material">
<color rgba="0.61568627450980395466 0.81176470588235294379 0.92941176470588238168 1.0"/>
</material>
</visual>
<collision>
<origin xyz="-0.050000000000000030531 -4.3541164367115040308e-20 -0.05300000000000000544" rpy="-4.1963440962894192726e-32 -1.3606706459783137366e-31 -9.8607613152626475676e-32" />
<geometry>
<mesh filename="package:///arm1.stl"/>
</geometry>
</collision>
<inertial>
<origin xyz="-0.050000000000000030531 6.6000575994366651149e-18 -0.027999999999999983236" rpy="0 0 0"/>
<mass value="0.053351215563702140965" />
<inertia ixx="4.7685000723111073309e-05" ixy="-4.7021041041518465688e-36"  ixz="1.4718608742308348961e-35" iyy="0.00012294175838236645528" iyz="-6.6192084170778203064e-36" izz="9.6727950022912305016e-05" />
</inertial>
</link>

<link name="armtwo_4">
<visual>
<origin xyz="0.10999999999999995892 0 -0.0029999999999999991951" rpy="3.141592653589793116 9.0913175461895563335e-32 -8.5961249970739943108e-19" />
<geometry>
<mesh filename="package:///armtwo.stl"/>
</geometry>
<material name="armtwo_material">
<color rgba="0.61568627450980395466 0.81176470588235294379 0.92941176470588238168 1.0"/>
</material>
</visual>
<collision>
<origin xyz="0.10999999999999995892 0 -0.0029999999999999991951" rpy="3.141592653589793116 9.0913175461895563335e-32 -8.5961249970739943108e-19" />
<geometry>
<mesh filename="package:///armtwo.stl"/>
</geometry>
</collision>
<inertial>
<origin xyz="0.054999999999999979461 1.5351170406140355147e-18 -0.025000000000000008327" rpy="0 0 0"/>
<mass value="0.061604201110935161156" />
<inertia ixx="3.5201315914225189967e-05" ixy="4.7710537079799043394e-23"  ixz="1.0890115208037315543e-35" iyy="0.00018430582427480415148" iyz="-1.1011415385495807607e-35" izz="0.00016639677522796493558" />
</inertial>
</link>

<joint name="elbow1" type="revolute">
<origin xyz="-0.1000000000000013517 5.3038223987374225059e-17 -0.0030000000000000096034" rpy="-4.1230608094467637014e-16 1.0190751307830435238e-15 3.1351784743271577938" />
<parent link="arm1_4" />
<child link="armtwo_4" />
<axis xyz="0 0 1"/>
<limit effort="1" velocity="20" lower="-1.0471975511965976313" upper="1.0471975511965976313"/>
<joint_properties friction="0.0"/>
</joint>

<joint name="main4" type="revolute">
<origin xyz="-0.033000000000000036249 0.10000000000000131006 -1.2106076136302722931e-17" rpy="1.57079632679489678 -4.4408920985008006972e-16 -1.5707963267948961139" />
<parent link="mainbody" />
<child link="arm1_4" />
<axis xyz="0 0 1"/>
<limit effort="1" velocity="20" lower="-0.52359877559829881566" upper="0.52359877559829881566"/>
<joint_properties friction="0.0"/>
</joint>


</robot>
